Workbook
Name VHD_TRUOC_THUE: VietHoaDon!$B$7
Name VHD_UU_TIEN_DG: VietHoaDon!$B$9
Name VHD_SL1_TO: VietHoaDon!$C$2
Name VHD_DG1_BE: VietHoaDon!$B$3
Name VHD_UU_TIEN_SL: VietHoaDon!$B$8
Name VHD_DG1_TO: VietHoaDon!$C$3
Name VHD_DG2_TO: VietHoaDon!$C$5
Name VHD_SL1_BE: VietHoaDon!$B$2
Name VHD_GIA_TRI_MUC_TIEU: VietHoaDon!$B$6
Name VHD_DG2_BE: VietHoaDon!$B$5
Name VHD_SL2_TO: VietHoaDon!$C$4
Name VHD_SL2_BE: VietHoaDon!$B$4

Sheet TonKho
A1: Mã hàng | B1: Tên hàng | C1: ĐVT | D1: Số lượng | E1: Giá trị | F1: Đơn giá BQ
A2: ONGTHEP | B2: Ống thép, Ống tôn mạ CN 20x40x1.4x6.0 | C2: kg | D2: 1834.13 | E2: 28512376 | F2: 15545.45
A3: THEPGOC | B3: Thép góc | C3: kg | D3: 0 | E3: -1.8626451e-09 | F3: 0
A4: THEPHINH | B4: Thép hình, Thép U, Thép I, Thép V, Thép H | C4: kg | D4: 1069.79 | E4: 16008404 | F4: 14964.062
A5: THEPHOP | B5: Thép hộp | C5: kg | D5: 10473.31 | E5: 1.571908e+08 | F5: 15008.703 | H5: ĐÃ CẬP NHẬT ĐẾN NGÀY
A6: THEPONG | B6: Thép ống | C6: kg | D6: 60.01 | E6: 874604.89 | F6: 14574.319 | H6: 46204
A7: THEPTAM | B7: Thép tấm | C7: kg | D7: 6923.941 | E7: 1.1160185e+08 | F7: 16118.256
A8: TONMA | B8: Tôn mạ | C8: kg | D8: 0 | E8: 0 | F8: 0
A9: XAGO | B9: Xà gồ | C9: kg | D9: 2588 | E9: 43289476 | F9: 16727
A10: TỔNG | D10: =SUM(tblTonKho[Số lượng]) -> 22949.181 | E10: =SUM(tblTonKho[Giá trị]) -> 3.5747751e+08

Sheet Nhap-Xuat
A1: STT | B1: Ngày | C1: Hóa đơn số | D1: Tên khách hàng | E1: Mã hàng | F1: Tên hàng | G1: Phân loại | H1: Số lượng | I1: Đơn giá | J1: Thành tiền | K1: Đơn giá BQ | L1: Số lượng tồn | M1: Giá trị tồn | N1: HashIndex | O1: InvoiceKey | P1: HĐ
A2: {=IF(B2:B1333="","", COUNTIFS(B2:B1333,"<"&B2:B1333) + COUNTIFS(B2:B1333,B2:B1333,G2:G1333,"<"&G2:G1333) + COUNTIFS(B2:B1333,B2:B1333,G2:G1333,G2:G1333,ROW(B2:B1333),"<="&ROW(B2:B1333)) )} -> 1 | B2: 41856 | C2: 750 | D2: CT TNHH Hoàng Mạnh | E2: THEPHINH | G2: NHAP | H2: 880 | I2: 15500 | J2: 13640000 | K2: 15500 | L2: 880 | M2: 13640000 | N2: e421f31badc311cde96791e067a8ea9489c5bf6e2ec852acb3584548ad250e50 | P2: {=IFERROR( HYPERLINK( "https://drive.google.com/file/d/"& XLOOKUP(O2,'Hoa-Don'!A:A,'Hoa-Don'!D:D) &"/view", "🔎" ), "" )}
A3: 2 | B3: 41860 | C3: 961 | D3: CT CP Thép Miền Bắc | E3: THEPTAM | G3: NHAP | H3: 9550 | I3: 11454.55 | J3: 1.0939095e+08 | K3: 11454.55 | L3: 9550 | M3: 1.0939095e+08 | N3: b6d89e982b5ae453f36ee36e1f582fb1eea369853dc01d0f8af50b8c22417820 | P3: {=IFERROR( HYPERLINK( "https://drive.google.com/file/d/"& XLOOKUP(O3,'Hoa-Don'!A:A,'Hoa-Don'!D:D) &"/view", "🔎" ), "" )}
A4: 3 | B4: 41866 | C4: 1 | D4: CT TNHH Hoàng Mạnh | E4: THEPTAM | G4: XUAT | H4: 850 | I4: 11454.55 | J4: 9736367.5 | K4: 11454.55 | L4: 8700 | M4: 99654585 | N4: 46ee886a93bcbc1c6546523a804ad89b5e970544740d67a463dae39e76586695 | P4: {=IFERROR( HYPERLINK( "https://drive.google.com/file/d/"& XLOOKUP(O4,'Hoa-Don'!A:A,'Hoa-Don'!D:D) &"/view", "🔎" ), "" )}
A5: 4 | B5: 41878 | C5: 3 | D5: Nguyễn Văn Nam | E5: THEPTAM | G5: XUAT | H5: 92 | I5: 11454.55 | J5: 1053818.6 | K5: 11454.55 | L5: 8608 | M5: 98600766 | N5: 281d646ba96a0f080dbf37dfd250a729bdb70548e420a6994e8bf7062a9c3c3e | P5: {=IFERROR( HYPERLINK( "https://drive.google.com/file/d/"& XLOOKUP(O5,'Hoa-Don'!A:A,'Hoa-Don'!D:D) &"/view", "🔎" ), "" )}
A6: 5 | B6: 41914 | C6: 5 | D6: CT CP Cầu Đuống Sông Hoá | E6: THEPTAM | G6: XUAT | H6: 147 | I6: 11454.55 | J6: 1683818.8 | K6: 11454.55 | L6: 8461 | M6: 96916948 | N6: c8112f99426176a5d60c06a8c8926009c2bebd739a34b1bb49fe85307a71d047 | P6: {=IFERROR( HYPERLINK( "https://drive.google.com/file/d/"& XLOOKUP(O6,'Hoa-Don'!A:A,'Hoa-Don'!D:D) &"/view", "🔎" ), "" )}
A7: 6 | B7: 41915 | C7: 6 | D7: CN CT TNHH MTV KTCTTL Bắc Thái Bình-xn Xây Lắp | E7: THEPTAM | G7: XUAT | H7: 1189 | I7: 11454.55 | J7: 13619460 | K7: 11454.55 | L7: 7272 | M7: 83297488 | N7: fabfe5daeaa3d857e2bb38fe1558e62ed7c02cb0a69d7e50fd3a887e9ff42957 | P7: {=IFERROR( HYPERLINK( "https://drive.google.com/file/d/"& XLOOKUP(O7,'Hoa-Don'!A:A,'Hoa-Don'!D:D) &"/view", "🔎" ), "" )}
A8: 7 | B8: 41915 | C8: 7 | D8: CT CP Tư Vấn Xây Dựng Và Thương Mại Bắc Đô | E8: THEPTAM | G8: XUAT | H8: 220 | I8: 11454.55 | J8: 2520001 | K8: 11454.55 | L8: 7052 | M8: 80777487 | N8: 14c3c526cd3c6df4d39693ed4bb790da6b66db3eae3b9b8125d5014b83b0d4b7 | P8: {=IFERROR( HYPERLINK( "https://drive.google.com/file/d/"& XLOOKUP(O8,'Hoa-Don'!A:A,'Hoa-Don'!D:D) &"/view", "🔎" ), "" )}
A9: 8 | B9: 41939 | C9: 2823 | D9: CT CP Sản Xuất Và Kinh Doanh Kim Khí | E9: THEPTAM | G9: NHAP | H9: 6290 | I9: 11000 | J9: 69190000 | K9: 11240.255 | L9: 13342 | M9: 1.4996749e+08 | N9: b33972b10f9b327a626faaed23ba4789d64ca194daa53cdfe4494a83e7a75aa5 | P9: {=IFERROR( HYPERLINK( "https://drive.google.com/file/d/"& XLOOKUP(O9,'Hoa-Don'!A:A,'Hoa-Don'!D:D) &"/view", "🔎" ), "" )}
A10: 9 | B10: 41956 | C10: 160 | D10: CT TNHH MTV Thép Hoàng Khang | E10: THEPHINH | G10: NHAP | H10: 1385 | I10: 13000 | J10: 18005000 | K10: 13971.302 | L10: 2265 | M10: 31645000 | N10: f9a1a8d2a54184fc26929ba2f7f7211b1df0f14a62a419b684342c61565c344a | P10: {=IFERROR( HYPERLINK( "https://drive.google.com/file/d/"& XLOOKUP(O10,'Hoa-Don'!A:A,'Hoa-Don'!D:D) &"/view", "🔎" ), "" )}
A11: 10 | B11: 41958 | C11: 8 | D11: CN CT TNHH MTV KTCTTL Bắc Thái Bình-xn Xây Lắp | E11: THEPTAM | G11: XUAT | H11: 1286 | I11: 11240.255 | J11: 14454968 | K11: 11240.255 | L11: 12056 | M11: 1.3551252e+08 | N11: b69ab2d41ab5567ba9026ee4beead63d0bea04ffe51b3dbf5d0ffb1992be0185 | P11: {=IFERROR( HYPERLINK( "https://drive.google.com/file/d/"& XLOOKUP(O11,'Hoa-Don'!A:A,'Hoa-Don'!D:D) &"/view", "🔎" ), "" )}
A12: 11 | B12: 41965 | C12: 178 | D12: CT TNHH MTV Thép Hoàng Khang | E12: THEPHINH | G12: NHAP | H12: 1380 | I12: 13000 | J12: 17940000 | K12: 13603.567 | L12: 3645 | M12: 49585000 | N12: 55b196e3abde4d77575c3c73a177dfec7531af8488de4b8f680578e43dddf896 | P12: {=IFERROR( HYPERLINK( "https://drive.google.com/file/d/"& XLOOKUP(O12,'Hoa-Don'!A:A,'Hoa-Don'!D:D) &"/view", "🔎" ), "" )}
A13: 12 | B13: 41967 | C13: 180 | D13: CT TNHH MTV Thép Hoàng Khang | E13: THEPHINH | G13: NHAP | H13: 1235 | I13: 13000 | J13: 16055000 | K13: 13450.82 | L13: 4880 | M13: 65640000 | N13: 030b91a3c22fad846b9422ad57305760c56720c613b911ada5873c34df930d67 | P13: {=IFERROR( HYPERLINK( "https://drive.google.com/file/d/"& XLOOKUP(O13,'Hoa-Don'!A:A,'Hoa-Don'!D:D) &"/view", "🔎" ), "" )}
A14: 13 | B14: 41969 | C14: 9 | D14: CN CT TNHH MTV KTCTTL Bắc Thái Bình-xn Xây Lắp | E14: THEPTAM | G14: XUAT | H14: 988 | I14: 11240.255 | J14: 11105372 | K14: 11240.255 | L14: 11068 | M14: 1.2440715e+08 | N14: 63f07129331634a3795fc82d45f9bde312ef9c3c337447d2a16b208a0cb2644f | P14: {=IFERROR( HYPERLINK( "https://drive.google.com/file/d/"& XLOOKUP(O14,'Hoa-Don'!A:A,'Hoa-Don'!D:D) &"/view", "🔎" ), "" )}
... A1118: 1117 | B1118: 45657 | C1118: 24 | D1118: CT TNHH Haiyang | E1118: THEPTAM | G1118: XUAT | H1118: 572 | I1118: 15858.214 | J1118: 9070898.6 | K1118: 15858.214 | L1118: 17351.24 | M1118: 2.7515968e+08 | N1118: 926dcda1ad3366a72b3216cc362fb8af3c476f5193fb65b2f9d009cb6ee1c7e7 | P1118: {=IFERROR( HYPERLINK( "https://drive.google.com/file/d/"& XLOOKUP(O1118,'Hoa-Don'!A:A,'Hoa-Don'!D:D) &"/view", "🔎" ), "" )}
A1119: 1118 | B1119: 45661 | C1119: 1 | D1119: CT CP Sản Xuất Và Thương Mại Tín Thành Hưng | E1119: THEPTAM | F1119: Thép tấm cắt theo yêu cầu | G1119: XUAT | H1119: 201 | I1119: 15858.214 | J1119: 3187501.1 | K1119: 15858.214 | L1119: 17150.24 | M1119: 2.7197218e+08 | N1119: 61eae8e6468b7e3b38a4e68059ae3815cafdbbd1e0eb49e0c5732ff6e65f8d0c | P1119: {=IFERROR( HYPERLINK( "https://drive.google.com/file/d/"& XLOOKUP(O1119,'Hoa-Don'!A:A,'Hoa-Don'!D:D) &"/view", "🔎" ), "" )}
A1120: 1119 | B1120: 45674 | C1120: 2 | D1120: CT TNHH XNK Thiết Bị Công Nghệ Cao FDI | E1120: THEPHINH | F1120: Thép hình U120 | G1120: XUAT | H1120: 695 | I1120: 16327.176 | J1120: 11347388 | K1120: 16327.176 | L1120: 45095.42 | M1120: 7.3628087e+08 | N1120: e37548a38d298c2cd02ab96e17546ad0c70532d64ba078d3545e1fccb23bcc04 | P1120: {=IFERROR( HYPERLINK( "https://drive.google.com/file/d/"& XLOOKUP(O1120,'Hoa-Don'!A:A,'Hoa-Don'!D:D) &"/view", "🔎" ), "" )}
A1121: 1120 | B1121: 45695 | C1121: 133 | D1121: CT TNHH Thương Mại Kim Khí Trường Phát | E1121: THEPHINH | F1121: Thép hình U100x6000 | G1121: NHAP | H1121: 1840 | I1121: 14272.73 | J1121: 26261823 | K1121: 16246.636 | L1121: 46935.42 | M1121: 7.625427e+08 | N1121: 70768812e68e5eed18f29789f47b906a782ac1c678631836c98e9c41d4b5289b | P1121: {=IFERROR( HYPERLINK( "https://drive.google.com/file/d/"& XLOOKUP(O1121,'Hoa-Don'!A:A,'Hoa-Don'!D:D) &"/view", "🔎" ), "" )}
A1122: 1121 | B1122: 45695 | C1122: 133 | D1122: CT TNHH Thương Mại Kim Khí Trường Phát | E1122: THEPHINH | F1122: Thép hình U120x6000 | G1122: NHAP | H1122: 2052 | I1122: 14363.64 | J1122: 29474189 | K1122: 16167.761 | L1122: 48987.42 | M1122: 7.9201689e+08 | N1122: 5505de878af03f3aadfad1a1d1e39bf6a9c7025f1cc77c7aa2f2fe7305fb86bd | P1122: {=IFERROR( HYPERLINK( "https://drive.google.com/file/d/"& XLOOKUP(O1122,'Hoa-Don'!A:A,'Hoa-Don'!D:D) &"/view", "🔎" ), "" )}
A1123: 1122 | B1123: 45695 | C1123: 133 | D1123: CT TNHH Thương Mại Kim Khí Trường Phát | E1123: THEPHINH | F1123: Thép hình U160x64x5x12000 | G1123: NHAP | H1123: 804 | I1123: 15181.82 | J1123: 12206183 | K1123: 16151.84 | L1123: 49791.42 | M1123: 8.0422307e+08 | N1123: c83ae41cbb1607fb6286dfcc6074107d3c329bda394a2f22d929a5e8c79726f3 | P1123: {=IFERROR( HYPERLINK( "https://drive.google.com/file/d/"& XLOOKUP(O1123,'Hoa-Don'!A:A,'Hoa-Don'!D:D) &"/view", "🔎" ), "" )}
A1124: 1123 | B1124: 45702 | C1124: 3 | D1124: CT CP Sản Xuất Và Thương Mại Tín Thành Hưng | E1124: THEPTAM | F1124: Thép tấm cắt theo yêu cầu | G1124: XUAT | H1124: 278 | I1124: 15858.214 | J1124: 4408583.6 | K1124: 15858.214 | L1124: 16872.24 | M1124: 2.675636e+08 | N1124: d7fcc31f69b400178eb22d7ce9af6c6eb2711328f1f73ac234dba2424ca65fe6 | P1124: {=IFERROR( HYPERLINK( "https://drive.google.com/file/d/"& XLOOKUP(O1124,'Hoa-Don'!A:A,'Hoa-Don'!D:D) &"/view", "🔎" ), "" )}
A1125: 1124 | B1125: 45703 | C1125: 4 | D1125: CT TNHH Sx Và Tm Kỹ Thuật Minh Quang | E1125: THEPHINH | F1125: Thép hình U60 | G1125: XUAT | H1125: 20 | I1125: 16151.84 | J1125: 323036.81 | K1125: 16151.84 | L1125: 49771.42 | M1125: 8.0390003e+08 | N1125: d631f9ce70955775c8ad24cd5098b47bd7be8e8dee777999fd0cdadd0ef380b1 | P1125: {=IFERROR( HYPERLINK( "https://drive.google.com/file/d/"& XLOOKUP(O1125,'Hoa-Don'!A:A,'Hoa-Don'!D:D) &"/view", "🔎" ), "" )}
A1126: 1125 | B1126: 45703 | C1126: 4 | D1126: CT TNHH Sx Và Tm Kỹ Thuật Minh Quang | E1126: THEPHINH | F1126: Thép hình U80 | G1126: XUAT | H1126: 108 | I1126: 16151.84 | J1126: 1744398.8 | K1126: 16151.84 | L1126: 49663.42 | M1126: 8.0215563e+08 | N1126: 8969bd6893081a606d0e90af4c1375ad88f546e839464e20c1dd694fc3ff98af | P1126: {=IFERROR( HYPERLINK( "https://drive.google.com/file/d/"& XLOOKUP(O1126,'Hoa-Don'!A:A,'Hoa-Don'!D:D) &"/view", "🔎" ), "" )}
A1127: 1126 | B1127: 45709 | C1127: 5 | D1127: CT TNHH Vận Tải VMS | E1127: THEPTAM | F1127: Thép tấm | G1127: XUAT | H1127: 853 | I1127: 15858.214 | J1127: 13527057 | K1127: 15858.214 | L1127: 16019.24 | M1127: 2.5403654e+08 | N1127: 8bec62893050ab27e06d895dec4f5a83ecc10ad60b04c180ec1ddb7e50a8102f | P1127: {=IFERROR( HYPERLINK( "https://drive.google.com/file/d/"& XLOOKUP(O1127,'Hoa-Don'!A:A,'Hoa-Don'!D:D) &"/view", "🔎" ), "" )}
A1128: 1127 | B1128: 45714 | C1128: 118 | D1128: CT TNHH Thép Hoàng Đào | E1128: THEPHINH | F1128: Thép hình | G1128: NHAP | H1128: 361.5 | I1128: 18000 | J1128: 6507000 | K1128: 16165.196 | L1128: 50024.92 | M1128: 8.0866263e+08 | N1128: 5350c4a2c90783c9a397818bf65389afd3432af0c236d2e69a9d2d557639d360 | P1128: {=IFERROR( HYPERLINK( "https://drive.google.com/file/d/"& XLOOKUP(O1128,'Hoa-Don'!A:A,'Hoa-Don'!D:D) &"/view", "🔎" ), "" )}
A1129: 1128 | B1129: 45715 | C1129: 6 | D1129: CT TNHH Haiyang | E1129: THEPTAM | F1129: Thép tấm 8mm | G1129: XUAT | H1129: 834 | I1129: 15858.214 | J1129: 13225751 | K1129: 15858.214 | L1129: 15185.24 | M1129: 2.4081079e+08 | N1129: 3b90dafac2389c61f35fe7aa5cc1d0beb3fd1bd920639d66ab5cac4943d5c8b2 | P1129: {=IFERROR( HYPERLINK( "https://drive.google.com/file/d/"& XLOOKUP(O1129,'Hoa-Don'!A:A,'Hoa-Don'!D:D) &"/view", "🔎" ), "" )}
A1130: 1129 | B1130: 45715 | C1130: 6 | D1130: CT TNHH Haiyang | E1130: THEPTAM | F1130: Thép tấm 20mm cắt theo yêu cầu | G1130: XUAT | H1130: 14.6 | I1130: 15858.214 | J1130: 231529.93 | K1130: 15858.214 | L1130: 15170.64 | M1130: 2.4057926e+08 | N1130: 9987a1f2c01efc30a2c26131372965a1974397339d164e8493deee908b4ab215 | P1130: {=IFERROR( HYPERLINK( "https://drive.google.com/file/d/"& XLOOKUP(O1130,'Hoa-Don'!A:A,'Hoa-Don'!D:D) &"/view", "🔎" ), "" )}
... A1247: 1246 | B1247: 46022 | C1247: 65 | D1247: CT TNHH 20-21 | E1247: THEPHINH | F1247: Thép hình các loại | G1247: XUAT | H1247: 4995.6 | I1247: 16008.729 | J1247: 79973206 | K1247: 16008.729 | L1247: 12793.02 | M1247: 2.0479999e+08 | N1247: c6ced4e2e7eae2bd41cd60adfc6eda285695f680215d9d7cc5917affd38cd356 | P1247: {=IFERROR( HYPERLINK( "https://drive.google.com/file/d/"& XLOOKUP(O1247,'Hoa-Don'!A:A,'Hoa-Don'!D:D) &"/view", "🔎" ), "" )}
A1248: 1247 | B1248: 46030 | C1248: 60 | D1248: CT TNHH Thương Mại Và Sản Xuất Thành Đạt Khoái Châu | E1248: THEPONG | F1248: Thép ống mạ kẽm F88.3x3.0x6000 | G1248: NHAP | H1248: 189.35 | I1248: 14389 | J1248: 2724557.1 | K1248: 14984.554 | L1248: 249.36 | M1248: 3736548.4 | N1248: 59760ee429437ea63751d2930efd386302a549e35d984f16c038ca72f9bed58c | O1248: 20260108_0900676665_60 | P1248: {=IFERROR( HYPERLINK( "https://drive.google.com/file/d/"& XLOOKUP(O1248,'Hoa-Don'!A:A,'Hoa-Don'!D:D) &"/view", "🔎" ), "" )} -> 🔎
A1249: 1248 | B1249: 46030 | C1249: 60 | D1249: CT TNHH Thương Mại Và Sản Xuất Thành Đạt Khoái Châu | E1249: THEPONG | F1249: Thép ống mạ kẽm F59.9x3.0x6000 | G1249: NHAP | H1249: 202.08 | I1249: 14389 | J1249: 2907729.1 | K1249: 14717.964 | L1249: 451.44 | M1249: 6644277.5 | N1249: 7656875e6d658008741b12f68b5178092910502ba9f9ac6f0d887d91c1036608 | O1249: 20260108_0900676665_60 | P1249: {=IFERROR( HYPERLINK( "https://drive.google.com/file/d/"& XLOOKUP(O1249,'Hoa-Don'!A:A,'Hoa-Don'!D:D) &"/view", "🔎" ), "" )} -> 🔎
A1250: 1249 | B1250: 46030 | C1250: 60 | D1250: CT TNHH Thương Mại Và Sản Xuất Thành Đạt Khoái Châu | E1250: THEPONG | F1250: Thép ống mạ kẽm F26.65x2.0x6000 | G1250: NHAP | H1250: 349.92 | I1250: 14389 | J1250: 5034998.9 | K1250: 14574.319 | L1250: 801.36 | M1250: 11679276 | N1250: f5a49646d515ceeaa29db526a73668e697b51d8778b1b4f2b0976f25cd47839d | O1250: 20260108_0900676665_60 | P1250: {=IFERROR( HYPERLINK( "https://drive.google.com/file/d/"& XLOOKUP(O1250,'Hoa-Don'!A:A,'Hoa-Don'!D:D) &"/view", "🔎" ), "" )} -> 🔎
A1251: 1250 | B1251: 46030 | C1251: 1 | D1251: CT CP Sản Xuất Và Thương Mại Tín Thành Hưng | E1251: THEPHINH | F1251: Thép hình các loại | G1251: XUAT | H1251: 289.99 | I1251: 16008.729 | J1251: 4642371.3 | K1251: 16008.729 | L1251: 12503.03 | M1251: 2.0015762e+08 | N1251: 0acbba6d5d9a2c60b96b6923878d6a05761ec946f450729aeba9575cf536c04b | P1251: {=IFERROR( HYPERLINK( "https://drive.google.com/file/d/"& XLOOKUP(O1251,'Hoa-Don'!A:A,'Hoa-Don'!D:D) &"/view", "🔎" ), "" )}
A1252: 1251 | B1252: 46032 | C1252: 2 | D1252: CT TNHH Cơ Khí Và Xây Dựng Hùng Dương | E1252: THEPONG | F1252: Thép ống mạ kẽm F88.3x3.0x6000 | G1252: XUAT | H1252: 189.35 | I1252: 14574.319 | J1252: 2759647.3 | K1252: 14574.319 | L1252: 612.01 | M1252: 8919629 | N1252: 430fe6a1d26568d5ca81d3eb8a56fd968de3ef6a48ae09e2a66b60b6269cd906 | P1252: {=IFERROR( HYPERLINK( "https://drive.google.com/file/d/"& XLOOKUP(O1252,'Hoa-Don'!A:A,'Hoa-Don'!D:D) &"/view", "🔎" ), "" )}
A1253: 1252 | B1253: 46032 | C1253: 2 | D1253: CT TNHH Cơ Khí Và Xây Dựng Hùng Dương | E1253: THEPONG | F1253: Thép ống mạ kẽm F59.9x3.0x6000 | G1253: XUAT | H1253: 202.08 | I1253: 14574.319 | J1253: 2945178.4 | K1253: 14574.319 | L1253: 409.93 | M1253: 5974450.6 | N1253: 1874dad8f4608b0a5b51cd4a30bf58b4cc3491987d6005dede732714d80bded8 | P1253: {=IFERROR( HYPERLINK( "https://drive.google.com/file/d/"& XLOOKUP(O1253,'Hoa-Don'!A:A,'Hoa-Don'!D:D) &"/view", "🔎" ), "" )}
A1254: 1253 | B1254: 46032 | C1254: 2 | D1254: CT TNHH Cơ Khí Và Xây Dựng Hùng Dương | E1254: THEPONG | F1254: Thép ống mạ kẽm F26.65x2.0x6000 | G1254: XUAT | H1254: 349.92 | I1254: 14574.319 | J1254: 5099845.7 | K1254: 14574.319 | L1254: 60.01 | M1254: 874604.89 | N1254: 82b87be02243c067747866119169bf61c5210ebf0891e35262d65ceef37969e7 | P1254: {=IFERROR( HYPERLINK( "https://drive.google.com/file/d/"& XLOOKUP(O1254,'Hoa-Don'!A:A,'Hoa-Don'!D:D) &"/view", "🔎" ), "" )}
A1255: 1254 | B1255: 46034 | C1255: 86 | D1255: CT TNHH Thương Mại Và Sản Xuất Thành Đạt Khoái Châu | E1255: THEPHOP | F1255: Thép hộp mạ kẽm 20x40x1.1x6000 | G1255: NHAP | H1255: 297 | I1255: 16000 | J1255: 4752000 | K1255: 15860.729 | L1255: 381.67 | M1255: 6053564.6 | N1255: 2a70fd3449545af50a1e6bb7ba616bd45c61e608fe5c059171c48eb058857883 | O1255: 20260112_0900676665_86 | P1255: {=IFERROR( HYPERLINK( "https://drive.google.com/file/d/"& XLOOKUP(O1255,'Hoa-Don'!A:A,'Hoa-Don'!D:D) &"/view", "🔎" ), "" )} -> 🔎
A1256: 1255 | B1256: 46034 | C1256: 6 | D1256: CT TNHH Anh Phúc | E1256: TONMA | F1256: Tôn mạ màu | G1256: NHAP | H1256: 2040.8 | I1256: 24500 | J1256: 49999600 | K1256: 24500 | L1256: 2040.8 | M1256: 49999600 | N1256: f4e5574870da782f246c2db4afd3a46953561b35f380fe4a7437088b12273ad6 | O1256: 20260112_1000511768_6 | P1256: {=IFERROR( HYPERLINK( "https://drive.google.com/file/d/"& XLOOKUP(O1256,'Hoa-Don'!A:A,'Hoa-Don'!D:D) &"/view", "🔎" ), "" )} -> 🔎
A1257: 1256 | B1257: 46034 | C1257: 3 | D1257: CT TNHH 20-21 | E1257: TONMA | F1257: Tôn mạ màu | G1257: XUAT | H1257: 2040.8 | I1257: 24500 | J1257: 49999600 | K1257: 0 | L1257: 0 | M1257: 0 | N1257: 10f8d6a7a086fe663c870dcb3a192258f38a8eaa43eceb6f9db9c0d0d175aa83 | P1257: {=IFERROR( HYPERLINK( "https://drive.google.com/file/d/"& XLOOKUP(O1257,'Hoa-Don'!A:A,'Hoa-Don'!D:D) &"/view", "🔎" ), "" )}
A1258: 1257 | B1258: 46037 | C1258: 5 | D1258: CT TNHH 20-21 | E1258: THEPTAM | F1258: Thép tấm các loại | G1258: XUAT | H1258: 1901.13 | I1258: 13514.253 | J1258: 25692351 | K1258: 13514.253 | L1258: 3751.07 | M1258: 50692908 | N1258: 5cb642147da3b0076cce3ecf8dfebd08bec0fc6b3b1d2beef4fb9d779f62c8a7 | P1258: {=IFERROR( HYPERLINK( "https://drive.google.com/file/d/"& XLOOKUP(O1258,'Hoa-Don'!A:A,'Hoa-Don'!D:D) &"/view", "🔎" ), "" )}
A1259: 1258 | B1259: 46037 | C1259: 5 | D1259: CT TNHH 20-21 | E1259: THEPHINH | F1259: Thép hình các loại | G1259: XUAT | H1259: 2756.92 | I1259: 16008.729 | J1259: 44134785 | K1259: 16008.729 | L1259: 9746.11 | M1259: 1.5602283e+08 | N1259: a27fdfec561db74e8e58ebdcff987d6b221883df05f2cfabe886b55b01f5d714 | P1259: {=IFERROR( HYPERLINK( "https://drive.google.com/file/d/"& XLOOKUP(O1259,'Hoa-Don'!A:A,'Hoa-Don'!D:D) &"/view", "🔎" ), "" )}
...

Sheet Hoa-Don
A1: invoiceKey | B1: XML_id | C1: XML_status | D1: PDF_id | E1: PDF_status | F1: View
A2: 20260309_1000677957_248 | B2: 1OeFgI4N2yeMgG_MyUYaO3tlfExMRFDTE | C2: ✔ | D2: 11btwXuuzIHQGifW9NeLCHxqedkBZ1NA9 | E2: ✔ | F2: {=IF(D2:D24="","",HYPERLINK("https://drive.google.com/file/d/"&D2:D24&"/view","🔎 Xem"))} -> 🔎 Xem
A3: 20261202_1000576500_30 | D3: 1R0kB6sDA5_nd_3rz5PY5V5SE0xIIXQkb | E3: ✔ | F3: 🔎 Xem
A4: 20260209_1000511768_40 | B4: 1qGY3MKDAu8k7eV7fHXMmZgiLHXwtdj1a | C4: ✔ | D4: 1G11gfytPIATmM0Nz0dCF9-yZccBXDpXE | E4: ✔ | F4: 🔎 Xem
A5: 20260112_0900676665_86 | B5: 1qq9ZcEqpDgslkXL1ARh8w1Kvi9ux-MLh | C5: ✔ | D5: 1YgqoTC7EfpUVdmNf4sFRJ6ug6giyM_ZX | E5: ✔ | F5: 🔎 Xem
A6: 20260112_1000511768_6 | B6: 1uMehHuRRbigu1BYRrl9rzwL3kxo8tfyn | C6: ✔ | D6: 1_aPiBrR47T4mi_8-SE3IUbAjhlJO6fhB | E6: ✔ | F6: 🔎 Xem
A7: 20260108_0900676665_60 | B7: 1wnigeryyI3cItsdwV6R3jXYFPZYwo_tF | C7: ✔ | D7: 1pPzWZA51Q9xeKVKhzivo3gLktqAA1KLC | E7: ✔ | F7: 🔎 Xem
A8: 20260318_4300847027_13 | B8: 1higSX8QqxSANLav61wxhpch8RiHg2Y9h | C8: ✔
A9: 20260318_1000451050_14 | B9: 12rI6g59uZq3eZ5-4o9hDZ7vIoce2ZIpR | C9: ✔
A10: 20260331_1001321047_15 | B10: 1KrqZuqRWr0yPp0A31Y3qB0v5fqaP4ygr | C10: ✔ | D10: 11bB-CYcfuPHexCvnaLBGarCMY4gA_irO | E10: ✔ | F10: 🔎 Xem
A11: 20260408_1000451050_16 | B11: 1ZlcMapqbzFzSdtLaaBT3fmckwXeTPQah | C11: ✔ | D11: 1Y3NCKYMwo0uFwzQ4gUuaHlKh_QGb_TOi | E11: ✔ | F11: 🔎 Xem
A12: 20260411_4300847027_17 | B12: 1Qp55PPtGDd8Zcm-bWsTZMUyjpfp9mIlE | C12: ✔ | D12: 1pUEGiwywYcuVfRcfTgI1tXKSYtA7LTvS | E12: ✔ | F12: 🔎 Xem
A13: 20260418_1001244025_18 | B13: 1D4I46Zz7xNsUsBUMcK5gOBhLeWgLUVPc | C13: ✔ | D13: 1BK2z7_aw6rPNnKYvdxup8BvpYjqWQTBy | E13: ✔ | F13: 🔎 Xem
A14: 20260422_0108132308_19 | B14: 1PQUXFeP8qwoSfNLyBebJDaPzQyfpjXve | C14: ✔ | D14: 1RVznr14qOPVxAvy8Ww33OLUU5dLfI0kz | E14: ✔ | F14: 🔎 Xem
A15: 20260428_1000451050_20 | B15: 1gq9OWRlRu1OTaUjhv_QitJYgPjmiQbTC | C15: ✔ | D15: 1LHAvI2shM-LVC7x6AdBii3hW-yX610QX | E15: ✔ | F15: 🔎 Xem
A16: 20260115_0108132308_4 | B16: 15yj93XnkfnJ3NCpghxb2Er07H2bQiDsi | C16: ✔ | D16: 1OeSAQLUfIEgqNkJ0hLQFdI84JrXPPtO3 | E16: ✔ | F16: 🔎 Xem
A17: 20260511_4300847027_21 | B17: 1bUcEdSGOn_4F51FFKKmi6OYylr61SNnN | C17: ✔ | D17: 1CutQAI3e4jDiqipbXTLD7zdYUrQVzQ0N | E17: ✔ | F17: 🔎 Xem
A18: 19700101_1000576500_101 | D18: 13NuAXwk2oUibT8cuWQpaTpdFNh6mHRab | E18: ✔ | F18: 🔎 Xem
A19: 20260514_0108132308_22 | B19: 11CkAJk0jiY0R9V_cL1ALt8V2SAOrBSqX | C19: ✔ | D19: 1U0RvGnKzALvNRGyv6zGzRkIjGPivrkmH | E19: ✔ | F19: 🔎 Xem
A20: 20260515_1001277292_23 | B20: 14ZKVjF8WfF0EdCrjn5Oyw_nrwDn0V6hg | C20: ✔ | D20: 1ZjamfbsByiSlJsYA9441UOCiyYYyiDR9 | E20: ✔ | F20: 🔎 Xem
A21: 20260517_1001277292_24 | B21: 1wfFUq_CTBF4_UQlzAge9GOzmQ6QfDiX0 | C21: ✔ | D21: 10sGjWbfqU418rkyAP6BWU-CvYG8pU4Nx | E21: ✔ | F21: 🔎 Xem
A22: 19700101_1000576500_102 | D22: 1QFOkov74g4CZSt1FYKy9y6Th3AZzXWsm | E22: ✔ | F22: 🔎 Xem
A23: 20260514_1000576500_102 | D23: 1cVVW9u2zwM7uA4UzjYeejciVRU-yNDZk | E23: ✔ | F23: 🔎 Xem
A24: 20260514_1000576500_101 | D24: 1RA68OGF3YehdY_cYsi-iQd5EIgmzg1Ha | E24: ✔ | F24: 🔎 Xem

Sheet MaHangHoa
A1: Mã hàng | B1: Tên hàng | C1: ĐVT
A2: THEPTAM | B2: Thép tấm | C2: kg
A3: THEPHINH | B3: Thép hình, Thép U, Thép I, Thép V, Thép H | C3: kg
A4: THEPHOP | B4: Thép hộp | C4: kg
A5: THEPONG | B5: Thép ống | C5: kg
A6: THEPGOC | B6: Thép góc | C6: kg
A7: XAGO | B7: Xà gồ | C7: kg
A8: ONGTHEP | B8: Ống thép, Ống tôn mạ CN 20x40x1.4x6.0 | C8: kg
A9: TONMA | B9: Tôn mạ | C9: kg
A10: Unknown_ID | B10: Chưa phân loại | C10: kg

Sheet PhanLoai
A1: P.loại
A2: NHAP
A3: XUAT

Sheet VietTat
A1: Tên đầy đủ | B1: Tên viết tắt
A2: Công Ty | B2: CT
A3: Trách Nhiệm Hữu Hạn | B3: TNHH
A4: Cổ Phần | B4: CP
A5: Một Thành Viên | B5: MTV
A6: Ct | B6: CT
A7: Tnhh | B7: TNHH
A8: Cp | B8: CP
A9: Mtv | B9: MTV
A10: Ktcttl | B10: KTCTTL
A11: Hts | B11: HTS
A12: Idico | B12: IDICO
... A28: Đầu Tư Xây Dựng Và Thương Mại Th | B28: Đầu Tư Xây Dựng Và Thương Mại TH

Sheet FileLog
A1: Dòng NX | B1: Ngày | C1: Mã hàng | D1: Diễn giải

Sheet VietHoaDon
A1: Trường | B1: Giá trị / Từ | C1: Đến | D1: Ghi chú | O1: SL1 | P1: ĐG1 | Q1: SL2 | R1: ĐG2 | S1: Giá trị
A2: SL mặt hàng 1 | D2: Named ranges: VHD_SL1_BE, VHD_SL1_TO
A3: ĐG mặt hàng 1 | D3: Named ranges: VHD_DG1_BE, VHD_DG1_TO
A4: SL mặt hàng 2 | D4: Named ranges: VHD_SL2_BE, VHD_SL2_TO; để trống nếu chỉ 1 mặt hàng
A5: ĐG mặt hàng 2 | D5: Named ranges: VHD_DG2_BE, VHD_DG2_TO; để trống nếu chỉ 1 mặt hàng
A6: Giá trị mục tiêu | D6: Named range: VHD_GIA_TRI_MUC_TIEU
A7: Trước thuế? | B7: TRUE | D7: TRUE: khớp trước thuế; FALSE: khớp sau thuế VAT 10%
A8: Ưu tiên SL nhỏ? | B8: FALSE | D8: Named range: VHD_UU_TIEN_SL
A9: Ưu tiên ĐG nhỏ? | B9: FALSE | D9: Named range: VHD_UU_TIEN_DG
